Traceback (most recent call last):
  File "/Users/yuchiaol_whoi/anaconda3/lib/python3.8/site-packages/jupyter_cache/executors/utils.py", line 51, in single_nb_execution
    executenb(
  File "/Users/yuchiaol_whoi/anaconda3/lib/python3.8/site-packages/nbclient/client.py", line 1087, in execute
    return NotebookClient(nb=nb, resources=resources, km=km, **kwargs).execute()
  File "/Users/yuchiaol_whoi/anaconda3/lib/python3.8/site-packages/nbclient/util.py", line 74, in wrapped
    return just_run(coro(*args, **kwargs))
  File "/Users/yuchiaol_whoi/anaconda3/lib/python3.8/site-packages/nbclient/util.py", line 53, in just_run
    return loop.run_until_complete(coro)
  File "/Users/yuchiaol_whoi/anaconda3/lib/python3.8/asyncio/base_events.py", line 616, in run_until_complete
    return future.result()
  File "/Users/yuchiaol_whoi/anaconda3/lib/python3.8/site-packages/nbclient/client.py", line 540, in async_execute
    await self.async_execute_cell(
  File "/Users/yuchiaol_whoi/anaconda3/lib/python3.8/site-packages/nbclient/client.py", line 832, in async_execute_cell
    self._check_raise_for_error(cell, exec_reply)
  File "/Users/yuchiaol_whoi/anaconda3/lib/python3.8/site-packages/nbclient/client.py", line 740, in _check_raise_for_error
    raise CellExecutionError.from_cell_and_msg(cell, exec_reply['content'])
nbclient.exceptions.CellExecutionError: An error occurred while executing the following cell:
------------------
# ================================================================
# main starts
# ================================================================
def main(inargs,year_st,year_ed):
    """Run the program."""

    print('program finishes here')

# ================================================================
# Describe this script and control flags
# ================================================================
if __name__ == '__main__':

   description='code template'

   parser = argparse.ArgumentParser(description=description)

   parser.add_argument("run_flag", type=str, help="False: do not run main program, just plotting figure; True: run the main program")

   args = parser.parse_args()

   plt.close('all')

   flag_rm_tropics = 1
   flag_Plumb = 0
   flag_long_term_basic_flow = 1

   np.set_printoptions(precision=5, suppress=True)

   plt.close('all')

   year = np.linspace(1979,2015,37)
------------------

An exception has occurred, use %tb to see the full traceback.

[0;31mSystemExit[0m[0;31m:[0m 2

SystemExit: 2

