Traceback (most recent call last):
  File "/Users/yuchiaol_whoi/anaconda3/lib/python3.8/site-packages/jupyter_cache/executors/utils.py", line 51, in single_nb_execution
    executenb(
  File "/Users/yuchiaol_whoi/anaconda3/lib/python3.8/site-packages/nbclient/client.py", line 1087, in execute
    return NotebookClient(nb=nb, resources=resources, km=km, **kwargs).execute()
  File "/Users/yuchiaol_whoi/anaconda3/lib/python3.8/site-packages/nbclient/util.py", line 74, in wrapped
    return just_run(coro(*args, **kwargs))
  File "/Users/yuchiaol_whoi/anaconda3/lib/python3.8/site-packages/nbclient/util.py", line 53, in just_run
    return loop.run_until_complete(coro)
  File "/Users/yuchiaol_whoi/anaconda3/lib/python3.8/asyncio/base_events.py", line 616, in run_until_complete
    return future.result()
  File "/Users/yuchiaol_whoi/anaconda3/lib/python3.8/site-packages/nbclient/client.py", line 540, in async_execute
    await self.async_execute_cell(
  File "/Users/yuchiaol_whoi/anaconda3/lib/python3.8/site-packages/nbclient/client.py", line 832, in async_execute_cell
    self._check_raise_for_error(cell, exec_reply)
  File "/Users/yuchiaol_whoi/anaconda3/lib/python3.8/site-packages/nbclient/client.py", line 740, in _check_raise_for_error
    raise CellExecutionError.from_cell_and_msg(cell, exec_reply['content'])
nbclient.exceptions.CellExecutionError: An error occurred while executing the following cell:
------------------
# ================================================================
# Yu-Chiao @ WHOI Feb 22, 2019
# Heirarchical cluster deomstration
# ================================================================

# ================================================================
# Import functions
# ================================================================
import argparse
from netCDF4 import Dataset
import numpy as np
import matplotlib.pyplot as plt
from matplotlib import mlab
import sys, os, ast
import matplotlib.path as mpath
import matplotlib as mpl
from pylab import setp

import cartopy.crs as ccrs
import cartopy.feature as cfeature
from cartopy.mpl.ticker import LongitudeFormatter, LatitudeFormatter
import cartopy.io.img_tiles as cimgt
from cartopy.io.img_tiles import StamenTerrain

from scipy.cluster.hierarchy import dendrogram, linkage
from scipy.cluster.hierarchy import cophenet
from scipy.spatial.distance import pdist
from scipy.cluster.hierarchy import fcluster
------------------

[0;31m---------------------------------------------------------------------------[0m
[0;31mModuleNotFoundError[0m                       Traceback (most recent call last)
[0;32m<ipython-input-1-14077b528fd0>[0m in [0;36m<module>[0;34m[0m
[1;32m      8[0m [0;31m# ================================================================[0m[0;34m[0m[0;34m[0m[0;34m[0m[0m
[1;32m      9[0m [0;32mimport[0m [0margparse[0m[0;34m[0m[0;34m[0m[0m
[0;32m---> 10[0;31m [0;32mfrom[0m [0mnetCDF4[0m [0;32mimport[0m [0mDataset[0m[0;34m[0m[0;34m[0m[0m
[0m[1;32m     11[0m [0;32mimport[0m [0mnumpy[0m [0;32mas[0m [0mnp[0m[0;34m[0m[0;34m[0m[0m
[1;32m     12[0m [0;32mimport[0m [0mmatplotlib[0m[0;34m.[0m[0mpyplot[0m [0;32mas[0m [0mplt[0m[0;34m[0m[0;34m[0m[0m

[0;31mModuleNotFoundError[0m: No module named 'netCDF4'
ModuleNotFoundError: No module named 'netCDF4'

